Namespace(biom_table='/mnt/home/djin/ceph/snakemake/data/Dan2020ASD_rl150/Dan2020ASD.biom', chains=4, control_group='Healthy', groups='Status', metadata_file='/mnt/home/djin/ceph/snakemake/data/Dan2020ASD_rl150/sample_metadata_JM_new.txt', monte_carlo_samples=1000, output_inference='/mnt/home/djin/ceph/snakemake/data/Dan2020ASD_rl150/Dan2020ASD.nc', processes=1)
Traceback (most recent call last):
  File "/mnt/home/djin/miniconda3/envs/birdman3.8/lib/python3.8/site-packages/pandas/core/indexes/base.py", line 3361, in get_loc
    return self._engine.get_loc(casted_key)
  File "pandas/_libs/index.pyx", line 76, in pandas._libs.index.IndexEngine.get_loc
  File "pandas/_libs/index.pyx", line 108, in pandas._libs.index.IndexEngine.get_loc
  File "pandas/_libs/hashtable_class_helper.pxi", line 5198, in pandas._libs.hashtable.PyObjectHashTable.get_item
  File "pandas/_libs/hashtable_class_helper.pxi", line 5206, in pandas._libs.hashtable.PyObjectHashTable.get_item
KeyError: 'batch_column'

The above exception was the direct cause of the following exception:

Traceback (most recent call last):
  File "disease_parallel.py", line 46, in <module>
    DiseaseSingle(table, metadata=metadata, feature_id=table.ids(axis='observation')[0],
  File "/mnt/ceph/users/djin/git/q2-differential/q2_differential/_model.py", line 115, in __init__
    cats = metadata[batch_column]
  File "/mnt/home/djin/miniconda3/envs/birdman3.8/lib/python3.8/site-packages/pandas/core/frame.py", line 3455, in __getitem__
    indexer = self.columns.get_loc(key)
  File "/mnt/home/djin/miniconda3/envs/birdman3.8/lib/python3.8/site-packages/pandas/core/indexes/base.py", line 3363, in get_loc
    raise KeyError(key) from err
KeyError: 'batch_column'
deleting tmpfiles dir: /tmp/tmp1qak0j1p
done
