Namespace(biom_table='/mnt/home/djin/ceph/ASD/Evans2022/vsearch/exported-feature-table/feature-table.biom', chains=4, control_group='ch16_control', groups='Genotype', metadata_file='/mnt/home/djin/ceph/ASD/Evans2022/vsearch/exported-feature-table/Metadata_group1_matched.txt', monte_carlo_samples=1000, output_inference='/mnt/home/djin/ceph/ASD/Evans2022/vsearch/exported-feature-table/test.nc', processes=128)
Traceback (most recent call last):
  File "/mnt/home/djin/miniconda3/envs/birdman3.8/lib/python3.8/site-packages/pandas/core/indexes/base.py", line 3361, in get_loc
    return self._engine.get_loc(casted_key)
  File "pandas/_libs/index.pyx", line 76, in pandas._libs.index.IndexEngine.get_loc
  File "pandas/_libs/index.pyx", line 108, in pandas._libs.index.IndexEngine.get_loc
  File "pandas/_libs/hashtable_class_helper.pxi", line 5198, in pandas._libs.hashtable.PyObjectHashTable.get_item
  File "pandas/_libs/hashtable_class_helper.pxi", line 5206, in pandas._libs.hashtable.PyObjectHashTable.get_item
KeyError: 'Status'

The above exception was the direct cause of the following exception:

Traceback (most recent call last):
  File "deseq2_parallel.py", line 46, in <module>
    SingleDESeq2(table, metadata=metadata, feature_id=table.ids(axis='observation')[0],
  File "/mnt/ceph/users/djin/git/q2-differential/q2_differential/_model.py", line 258, in __init__
    cats = metadata[category_column]
  File "/mnt/home/djin/miniconda3/envs/birdman3.8/lib/python3.8/site-packages/pandas/core/frame.py", line 3455, in __getitem__
    indexer = self.columns.get_loc(key)
  File "/mnt/home/djin/miniconda3/envs/birdman3.8/lib/python3.8/site-packages/pandas/core/indexes/base.py", line 3363, in get_loc
    raise KeyError(key) from err
KeyError: 'Status'
deleting tmpfiles dir: /tmp/tmp7sfw40a5
done
